2019-11-18 14:12:58,388 INFO: Microblog Startup [in /Users/noahcg/Desktop/microblog/app/__init__.py:72]
2019-11-18 14:13:05,460 ERROR: Exception on /edit_profile [POST] [in /Users/noahcg/Desktop/microblog/venv/lib/python3.6/site-packages/flask/app.py:1891]
Traceback (most recent call last):
  File "/Users/noahcg/Desktop/microblog/venv/lib/python3.6/site-packages/sqlalchemy/engine/base.py", line 1246, in _execute_context
    cursor, statement, parameters, context
  File "/Users/noahcg/Desktop/microblog/venv/lib/python3.6/site-packages/sqlalchemy/engine/default.py", line 581, in do_execute
    cursor.execute(statement, parameters)
sqlite3.IntegrityError: UNIQUE constraint failed: user.username

The above exception was the direct cause of the following exception:

Traceback (most recent call last):
  File "/Users/noahcg/Desktop/microblog/venv/lib/python3.6/site-packages/flask/app.py", line 2446, in wsgi_app
    response = self.full_dispatch_request()
  File "/Users/noahcg/Desktop/microblog/venv/lib/python3.6/site-packages/flask/app.py", line 1951, in full_dispatch_request
    rv = self.handle_user_exception(e)
  File "/Users/noahcg/Desktop/microblog/venv/lib/python3.6/site-packages/flask/app.py", line 1820, in handle_user_exception
    reraise(exc_type, exc_value, tb)
  File "/Users/noahcg/Desktop/microblog/venv/lib/python3.6/site-packages/flask/_compat.py", line 39, in reraise
    raise value
  File "/Users/noahcg/Desktop/microblog/venv/lib/python3.6/site-packages/flask/app.py", line 1949, in full_dispatch_request
    rv = self.dispatch_request()
  File "/Users/noahcg/Desktop/microblog/venv/lib/python3.6/site-packages/flask/app.py", line 1935, in dispatch_request
    return self.view_functions[rule.endpoint](**req.view_args)
  File "/Users/noahcg/Desktop/microblog/venv/lib/python3.6/site-packages/flask_login/utils.py", line 261, in decorated_view
    return func(*args, **kwargs)
  File "/Users/noahcg/Desktop/microblog/app/routes.py", line 120, in edit_profile
    db.session.commit()
  File "/Users/noahcg/Desktop/microblog/venv/lib/python3.6/site-packages/sqlalchemy/orm/scoping.py", line 162, in do
    return getattr(self.registry(), name)(*args, **kwargs)
  File "/Users/noahcg/Desktop/microblog/venv/lib/python3.6/site-packages/sqlalchemy/orm/session.py", line 1027, in commit
    self.transaction.commit()
  File "/Users/noahcg/Desktop/microblog/venv/lib/python3.6/site-packages/sqlalchemy/orm/session.py", line 494, in commit
    self._prepare_impl()
  File "/Users/noahcg/Desktop/microblog/venv/lib/python3.6/site-packages/sqlalchemy/orm/session.py", line 473, in _prepare_impl
    self.session.flush()
  File "/Users/noahcg/Desktop/microblog/venv/lib/python3.6/site-packages/sqlalchemy/orm/session.py", line 2470, in flush
    self._flush(objects)
  File "/Users/noahcg/Desktop/microblog/venv/lib/python3.6/site-packages/sqlalchemy/orm/session.py", line 2608, in _flush
    transaction.rollback(_capture_exception=True)
  File "/Users/noahcg/Desktop/microblog/venv/lib/python3.6/site-packages/sqlalchemy/util/langhelpers.py", line 68, in __exit__
    compat.reraise(exc_type, exc_value, exc_tb)
  File "/Users/noahcg/Desktop/microblog/venv/lib/python3.6/site-packages/sqlalchemy/util/compat.py", line 153, in reraise
    raise value
  File "/Users/noahcg/Desktop/microblog/venv/lib/python3.6/site-packages/sqlalchemy/orm/session.py", line 2568, in _flush
    flush_context.execute()
  File "/Users/noahcg/Desktop/microblog/venv/lib/python3.6/site-packages/sqlalchemy/orm/unitofwork.py", line 422, in execute
    rec.execute(self)
  File "/Users/noahcg/Desktop/microblog/venv/lib/python3.6/site-packages/sqlalchemy/orm/unitofwork.py", line 589, in execute
    uow,
  File "/Users/noahcg/Desktop/microblog/venv/lib/python3.6/site-packages/sqlalchemy/orm/persistence.py", line 236, in save_obj
    update,
  File "/Users/noahcg/Desktop/microblog/venv/lib/python3.6/site-packages/sqlalchemy/orm/persistence.py", line 996, in _emit_update_statements
    statement, multiparams
  File "/Users/noahcg/Desktop/microblog/venv/lib/python3.6/site-packages/sqlalchemy/engine/base.py", line 982, in execute
    return meth(self, multiparams, params)
  File "/Users/noahcg/Desktop/microblog/venv/lib/python3.6/site-packages/sqlalchemy/sql/elements.py", line 287, in _execute_on_connection
    return connection._execute_clauseelement(self, multiparams, params)
  File "/Users/noahcg/Desktop/microblog/venv/lib/python3.6/site-packages/sqlalchemy/engine/base.py", line 1101, in _execute_clauseelement
    distilled_params,
  File "/Users/noahcg/Desktop/microblog/venv/lib/python3.6/site-packages/sqlalchemy/engine/base.py", line 1250, in _execute_context
    e, statement, parameters, cursor, context
  File "/Users/noahcg/Desktop/microblog/venv/lib/python3.6/site-packages/sqlalchemy/engine/base.py", line 1476, in _handle_dbapi_exception
    util.raise_from_cause(sqlalchemy_exception, exc_info)
  File "/Users/noahcg/Desktop/microblog/venv/lib/python3.6/site-packages/sqlalchemy/util/compat.py", line 398, in raise_from_cause
    reraise(type(exception), exception, tb=exc_tb, cause=cause)
  File "/Users/noahcg/Desktop/microblog/venv/lib/python3.6/site-packages/sqlalchemy/util/compat.py", line 152, in reraise
    raise value.with_traceback(tb)
  File "/Users/noahcg/Desktop/microblog/venv/lib/python3.6/site-packages/sqlalchemy/engine/base.py", line 1246, in _execute_context
    cursor, statement, parameters, context
  File "/Users/noahcg/Desktop/microblog/venv/lib/python3.6/site-packages/sqlalchemy/engine/default.py", line 581, in do_execute
    cursor.execute(statement, parameters)
sqlalchemy.exc.IntegrityError: (sqlite3.IntegrityError) UNIQUE constraint failed: user.username
[SQL: UPDATE user SET username=?, about_me=? WHERE user.id = ?]
[parameters: ('susan', "Hi there! I'm the developer of this program. ", 3)]
(Background on this error at: http://sqlalche.me/e/gkpj)
2019-11-18 14:19:50,901 INFO: Microblog Startup [in /Users/noahcg/Desktop/microblog/app/__init__.py:72]
2019-11-18 14:46:20,478 INFO: Microblog Startup [in /Users/noahcg/Desktop/microblog/app/__init__.py:72]
2019-11-18 16:27:07,418 INFO: Microblog Startup [in /Users/noahcg/Desktop/microblog/app/__init__.py:72]
2019-11-18 16:28:08,345 INFO: Microblog Startup [in /Users/noahcg/Desktop/microblog/app/__init__.py:72]
2019-11-18 16:29:09,701 INFO: Microblog Startup [in /Users/noahcg/Desktop/microblog/app/__init__.py:72]
2019-11-19 11:59:15,019 INFO: Microblog Startup [in /Users/noahcg/Desktop/microblog/app/__init__.py:72]
2019-11-19 11:59:27,176 INFO: Microblog Startup [in /Users/noahcg/Desktop/microblog/app/__init__.py:72]
2019-11-19 12:04:02,157 INFO: Microblog startup [in /Users/noahcg/Desktop/microblog/app/__init__.py:72]
2019-11-19 12:04:13,721 INFO: Microblog startup [in /Users/noahcg/Desktop/microblog/app/__init__.py:72]
2019-11-19 15:26:54,030 INFO: Microblog startup [in /Users/noahcg/Desktop/microblog/app/__init__.py:72]
2019-11-19 15:31:20,803 INFO: Microblog startup [in /Users/noahcg/Desktop/microblog/app/__init__.py:72]
2019-11-19 15:31:31,090 ERROR: Exception on /joe [GET] [in /Users/noahcg/Desktop/microblog/venv/lib/python3.6/site-packages/flask/app.py:1891]
Traceback (most recent call last):
  File "/Users/noahcg/Desktop/microblog/venv/lib/python3.6/site-packages/flask/app.py", line 2446, in wsgi_app
    response = self.full_dispatch_request()
  File "/Users/noahcg/Desktop/microblog/venv/lib/python3.6/site-packages/flask/app.py", line 1951, in full_dispatch_request
    rv = self.handle_user_exception(e)
  File "/Users/noahcg/Desktop/microblog/venv/lib/python3.6/site-packages/flask/app.py", line 1820, in handle_user_exception
    reraise(exc_type, exc_value, tb)
  File "/Users/noahcg/Desktop/microblog/venv/lib/python3.6/site-packages/flask/_compat.py", line 39, in reraise
    raise value
  File "/Users/noahcg/Desktop/microblog/venv/lib/python3.6/site-packages/flask/app.py", line 1949, in full_dispatch_request
    rv = self.dispatch_request()
  File "/Users/noahcg/Desktop/microblog/venv/lib/python3.6/site-packages/flask/app.py", line 1935, in dispatch_request
    return self.view_functions[rule.endpoint](**req.view_args)
  File "/Users/noahcg/Desktop/microblog/app/routes.py", line 75, in joe
    param = request.get('foo','you didnt send anything')
  File "/Users/noahcg/Desktop/microblog/venv/lib/python3.6/site-packages/werkzeug/local.py", line 348, in __getattr__
    return getattr(self._get_current_object(), name)
AttributeError: 'Request' object has no attribute 'get'
2019-11-19 15:31:47,548 ERROR: Exception on /joe [GET] [in /Users/noahcg/Desktop/microblog/venv/lib/python3.6/site-packages/flask/app.py:1891]
Traceback (most recent call last):
  File "/Users/noahcg/Desktop/microblog/venv/lib/python3.6/site-packages/flask/app.py", line 2446, in wsgi_app
    response = self.full_dispatch_request()
  File "/Users/noahcg/Desktop/microblog/venv/lib/python3.6/site-packages/flask/app.py", line 1951, in full_dispatch_request
    rv = self.handle_user_exception(e)
  File "/Users/noahcg/Desktop/microblog/venv/lib/python3.6/site-packages/flask/app.py", line 1820, in handle_user_exception
    reraise(exc_type, exc_value, tb)
  File "/Users/noahcg/Desktop/microblog/venv/lib/python3.6/site-packages/flask/_compat.py", line 39, in reraise
    raise value
  File "/Users/noahcg/Desktop/microblog/venv/lib/python3.6/site-packages/flask/app.py", line 1949, in full_dispatch_request
    rv = self.dispatch_request()
  File "/Users/noahcg/Desktop/microblog/venv/lib/python3.6/site-packages/flask/app.py", line 1935, in dispatch_request
    return self.view_functions[rule.endpoint](**req.view_args)
  File "/Users/noahcg/Desktop/microblog/app/routes.py", line 75, in joe
    param = request.args.get('foo','you didnt send anything')
  File "/Users/noahcg/Desktop/microblog/venv/lib/python3.6/site-packages/werkzeug/local.py", line 348, in __getattr__
    return getattr(self._get_current_object(), name)
AttributeError: 'Request' object has no attribute 'get'
2019-11-19 15:31:54,230 INFO: Microblog startup [in /Users/noahcg/Desktop/microblog/app/__init__.py:72]
2019-11-19 15:34:13,026 INFO: Microblog startup [in /Users/noahcg/Desktop/microblog/app/__init__.py:72]
