2019-11-20 17:23:46,373 ERROR: Exception on /user/master [GET] [in /Users/noahcg/Desktop/microblog/venv/lib/python3.6/site-packages/flask/app.py:1891]
Traceback (most recent call last):
  File "/Users/noahcg/Desktop/microblog/venv/lib/python3.6/site-packages/flask/app.py", line 2446, in wsgi_app
    response = self.full_dispatch_request()
  File "/Users/noahcg/Desktop/microblog/venv/lib/python3.6/site-packages/flask/app.py", line 1951, in full_dispatch_request
    rv = self.handle_user_exception(e)
  File "/Users/noahcg/Desktop/microblog/venv/lib/python3.6/site-packages/flask/app.py", line 1820, in handle_user_exception
    reraise(exc_type, exc_value, tb)
  File "/Users/noahcg/Desktop/microblog/venv/lib/python3.6/site-packages/flask/_compat.py", line 39, in reraise
    raise value
  File "/Users/noahcg/Desktop/microblog/venv/lib/python3.6/site-packages/flask/app.py", line 1949, in full_dispatch_request
    rv = self.dispatch_request()
  File "/Users/noahcg/Desktop/microblog/venv/lib/python3.6/site-packages/flask/app.py", line 1935, in dispatch_request
    return self.view_functions[rule.endpoint](**req.view_args)
  File "/Users/noahcg/Desktop/microblog/venv/lib/python3.6/site-packages/flask_login/utils.py", line 261, in decorated_view
    return func(*args, **kwargs)
  File "/Users/noahcg/Desktop/microblog/app/routes.py", line 121, in user
    next_url=next_url, prev_url=prev_url)
  File "/Users/noahcg/Desktop/microblog/venv/lib/python3.6/site-packages/flask/helpers.py", line 370, in url_for
    return appctx.app.handle_url_build_error(error, endpoint, values)
  File "/Users/noahcg/Desktop/microblog/venv/lib/python3.6/site-packages/flask/app.py", line 2215, in handle_url_build_error
    reraise(exc_type, exc_value, tb)
  File "/Users/noahcg/Desktop/microblog/venv/lib/python3.6/site-packages/flask/_compat.py", line 39, in reraise
    raise value
  File "/Users/noahcg/Desktop/microblog/venv/lib/python3.6/site-packages/flask/helpers.py", line 358, in url_for
    endpoint, values, method=method, force_external=external
  File "/Users/noahcg/Desktop/microblog/venv/lib/python3.6/site-packages/werkzeug/routing.py", line 2020, in build
    raise BuildError(endpoint, values, method, self)
werkzeug.routing.BuildError: Could not build url for endpoint 'user/<username>'. Did you mean 'user' instead?
2019-11-20 17:23:51,868 INFO: Microblog startup [in /Users/noahcg/Desktop/microblog/app/__init__.py:72]
2019-11-20 17:23:55,363 ERROR: Exception on /user/master [GET] [in /Users/noahcg/Desktop/microblog/venv/lib/python3.6/site-packages/flask/app.py:1891]
Traceback (most recent call last):
  File "/Users/noahcg/Desktop/microblog/venv/lib/python3.6/site-packages/flask/app.py", line 2446, in wsgi_app
    response = self.full_dispatch_request()
  File "/Users/noahcg/Desktop/microblog/venv/lib/python3.6/site-packages/flask/app.py", line 1951, in full_dispatch_request
    rv = self.handle_user_exception(e)
  File "/Users/noahcg/Desktop/microblog/venv/lib/python3.6/site-packages/flask/app.py", line 1820, in handle_user_exception
    reraise(exc_type, exc_value, tb)
  File "/Users/noahcg/Desktop/microblog/venv/lib/python3.6/site-packages/flask/_compat.py", line 39, in reraise
    raise value
  File "/Users/noahcg/Desktop/microblog/venv/lib/python3.6/site-packages/flask/app.py", line 1949, in full_dispatch_request
    rv = self.dispatch_request()
  File "/Users/noahcg/Desktop/microblog/venv/lib/python3.6/site-packages/flask/app.py", line 1935, in dispatch_request
    return self.view_functions[rule.endpoint](**req.view_args)
  File "/Users/noahcg/Desktop/microblog/venv/lib/python3.6/site-packages/flask_login/utils.py", line 261, in decorated_view
    return func(*args, **kwargs)
  File "/Users/noahcg/Desktop/microblog/app/routes.py", line 121, in user
    next_url=next_url, prev_url=prev_url)
NameError: name 'next_url' is not defined
2019-11-20 17:24:02,925 ERROR: Exception on /user/master [GET] [in /Users/noahcg/Desktop/microblog/venv/lib/python3.6/site-packages/flask/app.py:1891]
Traceback (most recent call last):
  File "/Users/noahcg/Desktop/microblog/venv/lib/python3.6/site-packages/flask/app.py", line 2446, in wsgi_app
    response = self.full_dispatch_request()
  File "/Users/noahcg/Desktop/microblog/venv/lib/python3.6/site-packages/flask/app.py", line 1951, in full_dispatch_request
    rv = self.handle_user_exception(e)
  File "/Users/noahcg/Desktop/microblog/venv/lib/python3.6/site-packages/flask/app.py", line 1820, in handle_user_exception
    reraise(exc_type, exc_value, tb)
  File "/Users/noahcg/Desktop/microblog/venv/lib/python3.6/site-packages/flask/_compat.py", line 39, in reraise
    raise value
  File "/Users/noahcg/Desktop/microblog/venv/lib/python3.6/site-packages/flask/app.py", line 1949, in full_dispatch_request
    rv = self.dispatch_request()
  File "/Users/noahcg/Desktop/microblog/venv/lib/python3.6/site-packages/flask/app.py", line 1935, in dispatch_request
    return self.view_functions[rule.endpoint](**req.view_args)
  File "/Users/noahcg/Desktop/microblog/venv/lib/python3.6/site-packages/flask_login/utils.py", line 261, in decorated_view
    return func(*args, **kwargs)
  File "/Users/noahcg/Desktop/microblog/app/routes.py", line 121, in user
NameError: name 'next_url' is not defined
2019-11-20 17:24:11,249 INFO: Microblog startup [in /Users/noahcg/Desktop/microblog/app/__init__.py:72]
2019-11-20 17:27:24,202 INFO: Microblog startup [in /Users/noahcg/Desktop/microblog/app/__init__.py:72]
2019-11-20 17:27:28,108 ERROR: Exception on /user/master [GET] [in /Users/noahcg/Desktop/microblog/venv/lib/python3.6/site-packages/flask/app.py:1891]
Traceback (most recent call last):
  File "/Users/noahcg/Desktop/microblog/venv/lib/python3.6/site-packages/flask/app.py", line 2446, in wsgi_app
    response = self.full_dispatch_request()
  File "/Users/noahcg/Desktop/microblog/venv/lib/python3.6/site-packages/flask/app.py", line 1951, in full_dispatch_request
    rv = self.handle_user_exception(e)
  File "/Users/noahcg/Desktop/microblog/venv/lib/python3.6/site-packages/flask/app.py", line 1820, in handle_user_exception
    reraise(exc_type, exc_value, tb)
  File "/Users/noahcg/Desktop/microblog/venv/lib/python3.6/site-packages/flask/_compat.py", line 39, in reraise
    raise value
  File "/Users/noahcg/Desktop/microblog/venv/lib/python3.6/site-packages/flask/app.py", line 1949, in full_dispatch_request
    rv = self.dispatch_request()
  File "/Users/noahcg/Desktop/microblog/venv/lib/python3.6/site-packages/flask/app.py", line 1935, in dispatch_request
    return self.view_functions[rule.endpoint](**req.view_args)
  File "/Users/noahcg/Desktop/microblog/venv/lib/python3.6/site-packages/flask_login/utils.py", line 261, in decorated_view
    return func(*args, **kwargs)
  File "/Users/noahcg/Desktop/microblog/app/routes.py", line 115, in user
    page = request.args.get('page', 1, False)
  File "/Users/noahcg/Desktop/microblog/venv/lib/python3.6/site-packages/werkzeug/datastructures.py", line 320, in get
    rv = type(rv)
TypeError: 'bool' object is not callable
2019-11-20 17:28:14,111 INFO: Microblog startup [in /Users/noahcg/Desktop/microblog/app/__init__.py:72]
2019-11-21 11:25:20,655 INFO: Microblog startup [in /Users/noahcg/Desktop/microblog/app/__init__.py:74]
2019-11-21 11:27:42,902 INFO: Microblog startup [in /Users/noahcg/Desktop/microblog/app/__init__.py:74]
2019-11-21 11:31:06,346 INFO: Microblog startup [in /Users/noahcg/Desktop/microblog/app/__init__.py:74]
2019-11-21 11:37:24,086 INFO: Microblog startup [in /Users/noahcg/Desktop/microblog/app/__init__.py:74]
2019-11-21 11:39:28,754 INFO: Microblog startup [in /Users/noahcg/Desktop/microblog/app/__init__.py:74]
2019-11-21 15:55:13,142 INFO: Microblog startup [in /Users/noahcg/Desktop/microblog/app/__init__.py:74]
2019-11-21 15:55:26,265 ERROR: Exception on /reset_password_request [GET] [in /Users/noahcg/Desktop/microblog/venv/lib/python3.6/site-packages/flask/app.py:1891]
Traceback (most recent call last):
  File "/Users/noahcg/Desktop/microblog/venv/lib/python3.6/site-packages/flask/app.py", line 2446, in wsgi_app
    response = self.full_dispatch_request()
  File "/Users/noahcg/Desktop/microblog/venv/lib/python3.6/site-packages/flask/app.py", line 1951, in full_dispatch_request
    rv = self.handle_user_exception(e)
  File "/Users/noahcg/Desktop/microblog/venv/lib/python3.6/site-packages/flask/app.py", line 1820, in handle_user_exception
    reraise(exc_type, exc_value, tb)
  File "/Users/noahcg/Desktop/microblog/venv/lib/python3.6/site-packages/flask/_compat.py", line 39, in reraise
    raise value
  File "/Users/noahcg/Desktop/microblog/venv/lib/python3.6/site-packages/flask/app.py", line 1949, in full_dispatch_request
    rv = self.dispatch_request()
  File "/Users/noahcg/Desktop/microblog/venv/lib/python3.6/site-packages/flask/app.py", line 1935, in dispatch_request
    return self.view_functions[rule.endpoint](**req.view_args)
  File "/Users/noahcg/Desktop/microblog/app/routes.py", line 211, in reset_password_request
    if current.user.is_authenticated:
NameError: name 'current' is not defined
2019-11-21 15:56:03,714 INFO: Microblog startup [in /Users/noahcg/Desktop/microblog/app/__init__.py:74]
